Traceback (most recent call last):
  File "/opt/hostedtoolcache/Python/3.7.8/x64/lib/python3.7/site-packages/jupyter_cache/executors/basic.py", line 163, in execute
    executenb(nb_bundle.nb, cwd=tmpdirname, timeout=timeout)
  File "/opt/hostedtoolcache/Python/3.7.8/x64/lib/python3.7/site-packages/nbconvert/preprocessors/execute.py", line 737, in executenb
    return ep.preprocess(nb, resources, km=km)[0]
  File "/opt/hostedtoolcache/Python/3.7.8/x64/lib/python3.7/site-packages/nbconvert/preprocessors/execute.py", line 405, in preprocess
    nb, resources = super(ExecutePreprocessor, self).preprocess(nb, resources)
  File "/opt/hostedtoolcache/Python/3.7.8/x64/lib/python3.7/site-packages/nbconvert/preprocessors/base.py", line 69, in preprocess
    nb.cells[index], resources = self.preprocess_cell(cell, resources, index)
  File "/opt/hostedtoolcache/Python/3.7.8/x64/lib/python3.7/site-packages/nbconvert/preprocessors/execute.py", line 448, in preprocess_cell
    raise CellExecutionError.from_cell_and_msg(cell, out)
nbconvert.preprocessors.execute.CellExecutionError: An error occurred while executing the following cell:
------------------
nhanes_data['WeightLbs'] = nhanes_data['WeightLbs'] * 2.205
------------------

[0;31m---------------------------------------------------------------------------[0m
[0;31mKeyError[0m                                  Traceback (most recent call last)
[0;32m/opt/hostedtoolcache/Python/3.7.8/x64/lib/python3.7/site-packages/pandas/core/indexes/base.py[0m in [0;36mget_loc[0;34m(self, key, method, tolerance)[0m
[1;32m   2645[0m             [0;32mtry[0m[0;34m:[0m[0;34m[0m[0;34m[0m[0m
[0;32m-> 2646[0;31m                 [0;32mreturn[0m [0mself[0m[0;34m.[0m[0m_engine[0m[0;34m.[0m[0mget_loc[0m[0;34m([0m[0mkey[0m[0;34m)[0m[0;34m[0m[0;34m[0m[0m
[0m[1;32m   2647[0m             [0;32mexcept[0m [0mKeyError[0m[0;34m:[0m[0;34m[0m[0;34m[0m[0m

[0;32mpandas/_libs/index.pyx[0m in [0;36mpandas._libs.index.IndexEngine.get_loc[0;34m()[0m

[0;32mpandas/_libs/index.pyx[0m in [0;36mpandas._libs.index.IndexEngine.get_loc[0;34m()[0m

[0;32mpandas/_libs/hashtable_class_helper.pxi[0m in [0;36mpandas._libs.hashtable.PyObjectHashTable.get_item[0;34m()[0m

[0;32mpandas/_libs/hashtable_class_helper.pxi[0m in [0;36mpandas._libs.hashtable.PyObjectHashTable.get_item[0;34m()[0m

[0;31mKeyError[0m: 'WeightLbs'

During handling of the above exception, another exception occurred:

[0;31mKeyError[0m                                  Traceback (most recent call last)
[0;32m<ipython-input-13-c7352d2ea491>[0m in [0;36m<module>[0;34m[0m
[0;32m----> 1[0;31m [0mnhanes_data[0m[0;34m[[0m[0;34m'WeightLbs'[0m[0;34m][0m [0;34m=[0m [0mnhanes_data[0m[0;34m[[0m[0;34m'WeightLbs'[0m[0;34m][0m [0;34m*[0m [0;36m2.205[0m[0;34m[0m[0;34m[0m[0m
[0m
[0;32m/opt/hostedtoolcache/Python/3.7.8/x64/lib/python3.7/site-packages/pandas/core/frame.py[0m in [0;36m__getitem__[0;34m(self, key)[0m
[1;32m   2798[0m             [0;32mif[0m [0mself[0m[0;34m.[0m[0mcolumns[0m[0;34m.[0m[0mnlevels[0m [0;34m>[0m [0;36m1[0m[0;34m:[0m[0;34m[0m[0;34m[0m[0m
[1;32m   2799[0m                 [0;32mreturn[0m [0mself[0m[0;34m.[0m[0m_getitem_multilevel[0m[0;34m([0m[0mkey[0m[0;34m)[0m[0;34m[0m[0;34m[0m[0m
[0;32m-> 2800[0;31m             [0mindexer[0m [0;34m=[0m [0mself[0m[0;34m.[0m[0mcolumns[0m[0;34m.[0m[0mget_loc[0m[0;34m([0m[0mkey[0m[0;34m)[0m[0;34m[0m[0;34m[0m[0m
[0m[1;32m   2801[0m             [0;32mif[0m [0mis_integer[0m[0;34m([0m[0mindexer[0m[0;34m)[0m[0;34m:[0m[0;34m[0m[0;34m[0m[0m
[1;32m   2802[0m                 [0mindexer[0m [0;34m=[0m [0;34m[[0m[0mindexer[0m[0;34m][0m[0;34m[0m[0;34m[0m[0m

[0;32m/opt/hostedtoolcache/Python/3.7.8/x64/lib/python3.7/site-packages/pandas/core/indexes/base.py[0m in [0;36mget_loc[0;34m(self, key, method, tolerance)[0m
[1;32m   2646[0m                 [0;32mreturn[0m [0mself[0m[0;34m.[0m[0m_engine[0m[0;34m.[0m[0mget_loc[0m[0;34m([0m[0mkey[0m[0;34m)[0m[0;34m[0m[0;34m[0m[0m
[1;32m   2647[0m             [0;32mexcept[0m [0mKeyError[0m[0;34m:[0m[0;34m[0m[0;34m[0m[0m
[0;32m-> 2648[0;31m                 [0;32mreturn[0m [0mself[0m[0;34m.[0m[0m_engine[0m[0;34m.[0m[0mget_loc[0m[0;34m([0m[0mself[0m[0;34m.[0m[0m_maybe_cast_indexer[0m[0;34m([0m[0mkey[0m[0;34m)[0m[0;34m)[0m[0;34m[0m[0;34m[0m[0m
[0m[1;32m   2649[0m         [0mindexer[0m [0;34m=[0m [0mself[0m[0;34m.[0m[0mget_indexer[0m[0;34m([0m[0;34m[[0m[0mkey[0m[0;34m][0m[0;34m,[0m [0mmethod[0m[0;34m=[0m[0mmethod[0m[0;34m,[0m [0mtolerance[0m[0;34m=[0m[0mtolerance[0m[0;34m)[0m[0;34m[0m[0;34m[0m[0m
[1;32m   2650[0m         [0;32mif[0m [0mindexer[0m[0;34m.[0m[0mndim[0m [0;34m>[0m [0;36m1[0m [0;32mor[0m [0mindexer[0m[0;34m.[0m[0msize[0m [0;34m>[0m [0;36m1[0m[0;34m:[0m[0;34m[0m[0;34m[0m[0m

[0;32mpandas/_libs/index.pyx[0m in [0;36mpandas._libs.index.IndexEngine.get_loc[0;34m()[0m

[0;32mpandas/_libs/index.pyx[0m in [0;36mpandas._libs.index.IndexEngine.get_loc[0;34m()[0m

[0;32mpandas/_libs/hashtable_class_helper.pxi[0m in [0;36mpandas._libs.hashtable.PyObjectHashTable.get_item[0;34m()[0m

[0;32mpandas/_libs/hashtable_class_helper.pxi[0m in [0;36mpandas._libs.hashtable.PyObjectHashTable.get_item[0;34m()[0m

[0;31mKeyError[0m: 'WeightLbs'
KeyError: 'WeightLbs'

