Traceback (most recent call last):
  File "/miniconda/lib/python3.12/site-packages/jupyter_cache/executors/utils.py", line 58, in single_nb_execution
    executenb(
  File "/miniconda/lib/python3.12/site-packages/nbclient/client.py", line 1314, in execute
    return NotebookClient(nb=nb, resources=resources, km=km, **kwargs).execute()
           ^^^^^^^^^^^^^^^^^^^^^^^^^^^^^^^^^^^^^^^^^^^^^^^^^^^^^^^^^^^^^^^^^^^^^
  File "/miniconda/lib/python3.12/site-packages/jupyter_core/utils/__init__.py", line 165, in wrapped
    return loop.run_until_complete(inner)
           ^^^^^^^^^^^^^^^^^^^^^^^^^^^^^^
  File "/miniconda/lib/python3.12/asyncio/base_events.py", line 684, in run_until_complete
    return future.result()
           ^^^^^^^^^^^^^^^
  File "/miniconda/lib/python3.12/site-packages/nbclient/client.py", line 709, in async_execute
    await self.async_execute_cell(
  File "/miniconda/lib/python3.12/site-packages/nbclient/client.py", line 1062, in async_execute_cell
    await self._check_raise_for_error(cell, cell_index, exec_reply)
  File "/miniconda/lib/python3.12/site-packages/nbclient/client.py", line 918, in _check_raise_for_error
    raise CellExecutionError.from_cell_and_msg(cell, exec_reply_content)
nbclient.exceptions.CellExecutionError: An error occurred while executing the following cell:
------------------
import statsmodels.api as sm
table = sm.stats.Table.from_data(categorical_df, shift_zeros=False)
table.table_orig
------------------


[0;31m---------------------------------------------------------------------------[0m
[0;31mModuleNotFoundError[0m                       Traceback (most recent call last)
Cell [0;32mIn[2], line 1[0m
[0;32m----> 1[0m [38;5;28;01mimport[39;00m [38;5;21;01mstatsmodels[39;00m[38;5;21;01m.[39;00m[38;5;21;01mapi[39;00m [38;5;28;01mas[39;00m [38;5;21;01msm[39;00m
[1;32m      2[0m table [38;5;241m=[39m sm[38;5;241m.[39mstats[38;5;241m.[39mTable[38;5;241m.[39mfrom_data(categorical_df, shift_zeros[38;5;241m=[39m[38;5;28;01mFalse[39;00m)
[1;32m      3[0m table[38;5;241m.[39mtable_orig

[0;31mModuleNotFoundError[0m: No module named 'statsmodels'

