Traceback (most recent call last):
  File "/miniconda/lib/python3.12/site-packages/jupyter_cache/executors/utils.py", line 58, in single_nb_execution
    executenb(
  File "/miniconda/lib/python3.12/site-packages/nbclient/client.py", line 1314, in execute
    return NotebookClient(nb=nb, resources=resources, km=km, **kwargs).execute()
           ^^^^^^^^^^^^^^^^^^^^^^^^^^^^^^^^^^^^^^^^^^^^^^^^^^^^^^^^^^^^^^^^^^^^^
  File "/miniconda/lib/python3.12/site-packages/jupyter_core/utils/__init__.py", line 165, in wrapped
    return loop.run_until_complete(inner)
           ^^^^^^^^^^^^^^^^^^^^^^^^^^^^^^
  File "/miniconda/lib/python3.12/asyncio/base_events.py", line 684, in run_until_complete
    return future.result()
           ^^^^^^^^^^^^^^^
  File "/miniconda/lib/python3.12/site-packages/nbclient/client.py", line 709, in async_execute
    await self.async_execute_cell(
  File "/miniconda/lib/python3.12/site-packages/nbclient/client.py", line 1062, in async_execute_cell
    await self._check_raise_for_error(cell, cell_index, exec_reply)
  File "/miniconda/lib/python3.12/site-packages/nbclient/client.py", line 918, in _check_raise_for_error
    raise CellExecutionError.from_cell_and_msg(cell, exec_reply_content)
nbclient.exceptions.CellExecutionError: An error occurred while executing the following cell:
------------------
from statsmodels.formula.api import ols

ols_model = ols(formula='y ~ x + 1', data=simulated_data)
ols_result = ols_model.fit()
ols_result.summary()
------------------


[0;31m---------------------------------------------------------------------------[0m
[0;31mModuleNotFoundError[0m                       Traceback (most recent call last)
Cell [0;32mIn[3], line 1[0m
[0;32m----> 1[0m [38;5;28;01mfrom[39;00m [38;5;21;01mstatsmodels[39;00m[38;5;21;01m.[39;00m[38;5;21;01mformula[39;00m[38;5;21;01m.[39;00m[38;5;21;01mapi[39;00m [38;5;28;01mimport[39;00m ols
[1;32m      3[0m ols_model [38;5;241m=[39m ols(formula[38;5;241m=[39m[38;5;124m'[39m[38;5;124my ~ x + 1[39m[38;5;124m'[39m, data[38;5;241m=[39msimulated_data)
[1;32m      4[0m ols_result [38;5;241m=[39m ols_model[38;5;241m.[39mfit()

[0;31mModuleNotFoundError[0m: No module named 'statsmodels'

